2023-10-17 22:33:12 | ERROR    | __main__:run:138 | An error has been caught in function 'run', process 'MainProcess' (3555), thread 'MainThread' (140698000862080): - {}
Traceback (most recent call last):
  File "/home/runner/work/Epic_Auto/Epic_Auto/epic/src/claim.py", line 142, in <module>
    asyncio.run(run())
  File "/opt/hostedtoolcache/Python/3.10.13/x64/lib/python3.10/asyncio/runners.py", line 44, in run
    return loop.run_until_complete(main)
  File "/opt/hostedtoolcache/Python/3.10.13/x64/lib/python3.10/asyncio/base_events.py", line 636, in run_until_complete
    self.run_forever()
  File "/opt/hostedtoolcache/Python/3.10.13/x64/lib/python3.10/asyncio/base_events.py", line 603, in run_forever
    self._run_once()
  File "/opt/hostedtoolcache/Python/3.10.13/x64/lib/python3.10/asyncio/base_events.py", line 1909, in _run_once
    handle._run()
  File "/opt/hostedtoolcache/Python/3.10.13/x64/lib/python3.10/asyncio/events.py", line 80, in _run
    self._context.run(self._callback, *self._args)
> File "/home/runner/work/Epic_Auto/Epic_Auto/epic/src/claim.py", line 138, in run
    await agent.stash()
  File "/home/runner/work/Epic_Auto/Epic_Auto/epic/src/claim.py", line 131, in stash
    await self.claim_epic_games(context)
  File "/home/runner/work/Epic_Auto/Epic_Auto/epic/src/claim.py", line 86, in claim_epic_games
    if await epic.authorize(page):
  File "/home/runner/work/Epic_Auto/Epic_Auto/epic/src/services/agents/epic_games.py", line 190, in authorize
    match await self._login(page):
  File "/home/runner/work/Epic_Auto/Epic_Auto/epic/src/services/agents/epic_games.py", line 155, in _login
    await page.click("#login-with-epic")
  File "/opt/hostedtoolcache/Python/3.10.13/x64/lib/python3.10/site-packages/playwright/async_api/_generated.py", line 10101, in click
    await self._impl_obj.click(
  File "/opt/hostedtoolcache/Python/3.10.13/x64/lib/python3.10/site-packages/playwright/_impl/_page.py", line 691, in click
    return await self._main_frame.click(**locals_to_params(locals()))
  File "/opt/hostedtoolcache/Python/3.10.13/x64/lib/python3.10/site-packages/playwright/_impl/_frame.py", line 483, in click
    await self._channel.send("click", locals_to_params(locals()))
  File "/opt/hostedtoolcache/Python/3.10.13/x64/lib/python3.10/site-packages/playwright/_impl/_connection.py", line 61, in send
    return await self._connection.wrap_api_call(
  File "/opt/hostedtoolcache/Python/3.10.13/x64/lib/python3.10/site-packages/playwright/_impl/_connection.py", line 482, in wrap_api_call
    return await cb()
  File "/opt/hostedtoolcache/Python/3.10.13/x64/lib/python3.10/site-packages/playwright/_impl/_connection.py", line 97, in inner_send
    result = next(iter(done)).result()
playwright._impl._api_types.TimeoutError: Timeout 30000ms exceeded.
=========================== logs ===========================
waiting for locator("#login-with-epic")
============================================================
